<?xml version="1.0" ?>
<mujoco model="factory_hall_logo_fixed">
  <option timestep="0.001" gravity="0 0 -9.81" integrator="RK4" solver="PGS"/>
  <default>
    <joint limited="false" armature="0.01"/>
    <equality solref="0.0002 1" solimp="0.99 0.99 0.0001"/>
  </default>
  <visual>
    <headlight diffuse="0.6 0.6 0.6" ambient="0.3 0.3 0.3"/>
    <rgba fog="0.10 0.12 0.14 1" rangefinder="0 0 1 0.1"/>
    <global azimuth="120" elevation="-20"/>
  </visual>
  <asset>
    <texture type="skybox" builtin="gradient" rgb1="0.05 0.08 0.12" rgb2="0.25 0.27 0.30" width="512" height="3072"/>
    <material name="floor_mat" rgba="0.6 0.6 0.6 1" reflectance="0.3"/>
    <texture name="kmu_logo_tex" type="2d" file="/Users/hkim/Documents/shared_UROP/toy_project/mujoco_llm/asset/robotis_tb3/Signature_KMU.png"/>
    <material name="logo_mat" texture="kmu_logo_tex" texuniform="true"/>
    <mesh name="burger_base" file="/Users/hkim/Documents/shared_UROP/toy_project/mujoco_llm/asset/robotis_tb3/burger_base.stl" scale="0.001 0.001 0.001"/>
    <mesh name="left_tire" file="/Users/hkim/Documents/shared_UROP/toy_project/mujoco_llm/asset/robotis_tb3/left_tire.stl" scale="0.001 0.001 0.001"/>
    <mesh name="right_tire" file="/Users/hkim/Documents/shared_UROP/toy_project/mujoco_llm/asset/robotis_tb3/right_tire.stl" scale="0.001 0.001 0.001"/>
    <mesh name="lds" file="/Users/hkim/Documents/shared_UROP/toy_project/mujoco_llm/asset/robotis_tb3/lds.stl" scale="0.001 0.001 0.001"/>
    <mesh name="camera" file="/Users/hkim/Documents/shared_UROP/toy_project/mujoco_llm/asset/robotis_tb3/camera.stl"/>
    <mesh name="lidar" file="/Users/hkim/Documents/shared_UROP/toy_project/mujoco_llm/asset/robotis_tb3/lidar.stl" scale="0.001 0.001 0.001"/>
    <mesh name="ul_sensor" file="/Users/hkim/Documents/shared_UROP/toy_project/mujoco_llm/asset/robotis_tb3/ul_sensor.stl"/>
  </asset>
  <worldbody>
    <light pos="0 0 8" dir="0 0 -1" directional="true"/>
    <geom name="floor_base" type="plane" size="8 6 0.05" material="floor_mat"/>
    <geom name="floor_logo" type="box" pos="0 0 0.001" size="1.5 1.5 0.0005" material="logo_mat"/>
    <geom name="wall_front" type="box" pos="0 6 0.5" size="8 0.1 0.5" rgba="0.18 0.20 0.3 1"/>
    <geom name="wall_back" type="box" pos="0 -6 0.5" size="8 0.1 0.5" rgba="0.18 0.20 0.3 1"/>
    <geom name="wall_left" type="box" pos="-8 0 0.5" size="0.1 6 0.5" rgba="0.18 0.20 0.3 1"/>
    <geom name="wall_right" type="box" pos="8 0 0.5" size="0.1 6 0.5" rgba="0.18 0.20 0.3 1"/>
    <body name="base" pos="0 0 0" euler="0 0 0">
      <joint type="free" name="base_joint"/>
      <geom pos="-0.032 0 0.01" type="mesh" rgba="0.4 0.4 0.4 1" mesh="burger_base"/>
      <geom size="0.015 0.0045 0.01" pos="-0.081 7.96327e-07 0.005" quat="0.707388 -0.706825 0 0" type="box"/>
      <geom pos="-0.032 0 0.182" quat="1 0 0 0" type="mesh" rgba="0.3 0.3 0.3 1" mesh="lds"/>
      <body name="wheel_left_link" pos="0 0.08 0.033" quat="0.707388 -0.706825 0 0">
        <inertial pos="0 0 0" quat="-0.000890159 0.706886 0.000889646 0.707326" mass="0.0284989" diaginertia="2.07126e-05 1.11924e-05 1.11756e-05"/>
        <joint name="wheel_left_joint" pos="0 0 0" axis="0 0 1"/>
        <geom quat="0.707388 0.706825 0 0" type="mesh" rgba="0.3 0.3 0.3 1" mesh="left_tire"/>
      </body>
      <body name="wheel_right_link" pos="0 -0.08 0.033" quat="0.707388 -0.706825 0 0">
        <inertial pos="0 0 0" quat="-0.000890159 0.706886 0.000889646 0.707326" mass="0.0284989" diaginertia="2.07126e-05 1.11924e-05 1.11756e-05"/>
        <joint name="wheel_right_joint" pos="0 0 0" axis="0 0 1"/>
        <geom quat="0.707388 0.706825 0 0" type="mesh" rgba="0.3 0.3 0.3 1" mesh="right_tire"/>
      </body>
      <body name="imu_link" pos="0 0 0.05">
        <site name="imu" pos="0 0 0"/>
      </body>
      <body name="camera_mount" pos="0.05 0 0.15">
        <body name="camera_link" pos="0 0 0">
          <geom type="mesh" mesh="camera" rgba="0.31 0.64 0.41 1.0" pos="0 0 0"/>
          <camera name="camera" mode="fixed" fovy="60" xyaxes="0 -1 0 0 0 1"/>
        </body>
      </body>
      <body name="lidar_mount" pos="-0.032 0 0.172">
        <body name="laser_link" pos="0 0 0">
          <geom type="mesh" mesh="lidar" rgba="0.1 0.1 0.1 1" pos="0 0 0"/>
          <replicate count="360" euler="0 0 1">
            <site name="rf" size="0.001 0.001 0.001" rgba="0 0 0 0" pos="0.0 0.0 0.03" zaxis="1 0 0"/>
          </replicate>
        </body>
      </body>
      <body name="ul_sensor_mount" pos="0.05 0 0.04">
        <body name="ul_sensor_link" pos="0 0 0">
          <geom type="mesh" mesh="ul_sensor" rgba="0.07 0.34 0.63 1.0" pos="0 0 0"/>
        </body>
      </body>
    </body>
  </worldbody>
  <actuator>
    <velocity name="wheel_left_actuator" ctrllimited="true" ctrlrange="-30.0 30.0" gear="1" kv="1.0" joint="wheel_left_joint"/>
    <velocity name="wheel_right_actuator" ctrllimited="true" ctrlrange="-30.0 30.0" gear="1" kv="1.0" joint="wheel_right_joint"/>
  </actuator>
  <sensor>
    <rangefinder name="laser" site="rf" cutoff="3.0"/>
    <accelerometer name="accelerometer" site="imu"/>
    <gyro name="gyro" site="imu"/>
    <velocimeter name="velocimeter" site="imu"/>
  </sensor>
</mujoco>
